Workbook

Sheet Ringkasan
A1: Ringkasan perbandingan
A2: Semua angka dihitung dari sheet 'Matriks Fitur'. Ubah status di sana dan angka di sini ikut berubah.
A4: Status | B4: MELD | C4: Monveo | D4: Aplikasi Anda
A5: Ada | B5: =COUNTIF('Matriks Fitur'!$D$5:$D$86,$A5) -> 35 | C5: =COUNTIF('Matriks Fitur'!$F$5:$F$86,$A5) -> 32 | D5: =COUNTIF('Matriks Fitur'!$H$5:$H$86,$A5) -> 4
A6: Ada (klaim) | B6: =COUNTIF('Matriks Fitur'!$D$5:$D$86,$A6) -> 18 | C6: =COUNTIF('Matriks Fitur'!$F$5:$F$86,$A6) -> 1 | D6: =COUNTIF('Matriks Fitur'!$H$5:$H$86,$A6) -> 0
A7: Pro | B7: =COUNTIF('Matriks Fitur'!$D$5:$D$86,$A7) -> 4 | C7: =COUNTIF('Matriks Fitur'!$F$5:$F$86,$A7) -> 1 | D7: =COUNTIF('Matriks Fitur'!$H$5:$H$86,$A7) -> 0
A8: Sebagian | B8: =COUNTIF('Matriks Fitur'!$D$5:$D$86,$A8) -> 2 | C8: =COUNTIF('Matriks Fitur'!$F$5:$F$86,$A8) -> 2 | D8: =COUNTIF('Matriks Fitur'!$H$5:$H$86,$A8) -> 8
A9: Tidak terlihat | B9: =COUNTIF('Matriks Fitur'!$D$5:$D$86,$A9) -> 9 | C9: =COUNTIF('Matriks Fitur'!$F$5:$F$86,$A9) -> 29 | D9: =COUNTIF('Matriks Fitur'!$H$5:$H$86,$A9) -> 57
A10: Perlu cek | B10: =COUNTIF('Matriks Fitur'!$D$5:$D$86,$A10) -> 14 | C10: =COUNTIF('Matriks Fitur'!$F$5:$F$86,$A10) -> 17 | D10: =COUNTIF('Matriks Fitur'!$H$5:$H$86,$A10) -> 13
A11: Total fitur | B11: =SUM(B5:B10) -> 82 | C11: =SUM(C5:C10) -> 82 | D11: =SUM(D5:D10) -> 82
A12: Cakupan (Ada + klaim + Pro) / total | B12: =IF(B11=0,0,(B5+B6+B7)/B11) -> 0.69512195 | C12: =IF(C11=0,0,(C5+C6+C7)/C11) -> 0.41463415 | D12: =IF(D11=0,0,(D5+D6+D7)/D11) -> 0.048780488
A15: Penilaian untuk aplikasi Anda | B15: Jumlah fitur
A16: GAP BESAR | B16: =COUNTIF('Matriks Fitur'!$K$5:$K$86,A16) -> 15 | C16: Dua pesaing punya, kita belum atau baru sebagian
A17: GAP | B17: =COUNTIF('Matriks Fitur'!$K$5:$K$86,A17) -> 36 | C17: Satu pesaing punya, kita belum atau baru sebagian
A18: VERIFIKASI | B18: =COUNTIF('Matriks Fitur'!$K$5:$K$86,A18) -> 13 | C18: Status kita belum diisi (Perlu cek)
A19: Setara | B19: =COUNTIF('Matriks Fitur'!$K$5:$K$86,A19) -> 3 | C19: Pesaing punya dan kita juga Ada
A20: KEUNGGULAN UNIK | B20: =COUNTIF('Matriks Fitur'!$K$5:$K$86,A20) -> 0 | C20: Hanya kita yang Ada
A21: CEK PESAING | B21: =COUNTIF('Matriks Fitur'!$K$5:$K$86,A21) -> 1 | C21: Kita Ada, tetapi status pesaing belum dipastikan, jadi belum bisa disebut unik
A22: PELUANG | B22: =COUNTIF('Matriks Fitur'!$K$5:$K$86,A22) -> 9 | C22: Pesaing dipastikan belum punya (termasuk rencana kita)
A23: PELUANG (cek) | B23: =COUNTIF('Matriks Fitur'!$K$5:$K$86,A23) -> 5 | C23: Belum ada pesaing yang terlihat punya, tetapi satu pesaing masih Perlu cek
A26: Kelompok fitur | B26: Total | C26: Gap (besar + biasa) | D26: Prioritas Tinggi yang masih gap
A27: Capture & input | B27: =COUNTIF('Matriks Fitur'!$B$5:$B$86,A27) -> 18 | C27: =COUNTIFS('Matriks Fitur'!$B$5:$B$86,A27,'Matriks Fitur'!$K$5:$K$86,"GAP*") -> 12 | D27: =COUNTIFS('Matriks Fitur'!$B$5:$B$86,A27,'Matriks Fitur'!$K$5:$K$86,"GAP*",'Matriks Fitur'!$L$5:$L$86,"Tinggi") -> 4
A28: Akun & kategori | B28: =COUNTIF('Matriks Fitur'!$B$5:$B$86,A28) -> 10 | C28: =COUNTIFS('Matriks Fitur'!$B$5:$B$86,A28,'Matriks Fitur'!$K$5:$K$86,"GAP*") -> 6 | D28: =COUNTIFS('Matriks Fitur'!$B$5:$B$86,A28,'Matriks Fitur'!$K$5:$K$86,"GAP*",'Matriks Fitur'!$L$5:$L$86,"Tinggi") -> 2
A29: Tagihan & berulang | B29: =COUNTIF('Matriks Fitur'!$B$5:$B$86,A29) -> 8 | C29: =COUNTIFS('Matriks Fitur'!$B$5:$B$86,A29,'Matriks Fitur'!$K$5:$K$86,"GAP*") -> 6 | D29: =COUNTIFS('Matriks Fitur'!$B$5:$B$86,A29,'Matriks Fitur'!$K$5:$K$86,"GAP*",'Matriks Fitur'!$L$5:$L$86,"Tinggi") -> 2
A30: Perencanaan | B30: =COUNTIF('Matriks Fitur'!$B$5:$B$86,A30) -> 9 | C30: =COUNTIFS('Matriks Fitur'!$B$5:$B$86,A30,'Matriks Fitur'!$K$5:$K$86,"GAP*") -> 6 | D30: =COUNTIFS('Matriks Fitur'!$B$5:$B$86,A30,'Matriks Fitur'!$K$5:$K$86,"GAP*",'Matriks Fitur'!$L$5:$L$86,"Tinggi") -> 2
A31: Analitik | B31: =COUNTIF('Matriks Fitur'!$B$5:$B$86,A31) -> 4 | C31: =COUNTIFS('Matriks Fitur'!$B$5:$B$86,A31,'Matriks Fitur'!$K$5:$K$86,"GAP*") -> 3 | D31: =COUNTIFS('Matriks Fitur'!$B$5:$B$86,A31,'Matriks Fitur'!$K$5:$K$86,"GAP*",'Matriks Fitur'!$L$5:$L$86,"Tinggi") -> 0
A32: Kolaborasi | B32: =COUNTIF('Matriks Fitur'!$B$5:$B$86,A32) -> 9 | C32: =COUNTIFS('Matriks Fitur'!$B$5:$B$86,A32,'Matriks Fitur'!$K$5:$K$86,"GAP*") -> 9 | D32: =COUNTIFS('Matriks Fitur'!$B$5:$B$86,A32,'Matriks Fitur'!$K$5:$K$86,"GAP*",'Matriks Fitur'!$L$5:$L$86,"Tinggi") -> 1
A33: Keamanan & privasi | B33: =COUNTIF('Matriks Fitur'!$B$5:$B$86,A33) -> 5 | C33: =COUNTIFS('Matriks Fitur'!$B$5:$B$86,A33,'Matriks Fitur'!$K$5:$K$86,"GAP*") -> 2 | D33: =COUNTIFS('Matriks Fitur'!$B$5:$B$86,A33,'Matriks Fitur'!$K$5:$K$86,"GAP*",'Matriks Fitur'!$L$5:$L$86,"Tinggi") -> 1
A34: Platform & UX | B34: =COUNTIF('Matriks Fitur'!$B$5:$B$86,A34) -> 8 | C34: =COUNTIFS('Matriks Fitur'!$B$5:$B$86,A34,'Matriks Fitur'!$K$5:$K$86,"GAP*") -> 4 | D34: =COUNTIFS('Matriks Fitur'!$B$5:$B$86,A34,'Matriks Fitur'!$K$5:$K$86,"GAP*",'Matriks Fitur'!$L$5:$L$86,"Tinggi") -> 0
A35: Bisnis & pertumbuhan | B35: =COUNTIF('Matriks Fitur'!$B$5:$B$86,A35) -> 3 | C35: =COUNTIFS('Matriks Fitur'!$B$5:$B$86,A35,'Matriks Fitur'!$K$5:$K$86,"GAP*") -> 3 | D35: =COUNTIFS('Matriks Fitur'!$B$5:$B$86,A35,'Matriks Fitur'!$K$5:$K$86,"GAP*",'Matriks Fitur'!$L$5:$L$86,"Tinggi") -> 0
A36: Pembeda rencana kita | B36: =COUNTIF('Matriks Fitur'!$B$5:$B$86,A36) -> 8 | C36: =COUNTIFS('Matriks Fitur'!$B$5:$B$86,A36,'Matriks Fitur'!$K$5:$K$86,"GAP*") -> 0 | D36: =COUNTIFS('Matriks Fitur'!$B$5:$B$86,A36,'Matriks Fitur'!$K$5:$K$86,"GAP*",'Matriks Fitur'!$L$5:$L$86,"Tinggi") -> 0
A37: Total | B37: =SUM(B27:B36) -> 82 | C37: =SUM(C27:C36) -> 51 | D37: =SUM(D27:D36) -> 12

Sheet Matriks Fitur
A1: Matriks fitur: MELD vs Monveo vs aplikasi Anda (my-financial-manager.online)
A2: Kolom 'Status kita' dan 'Prioritas' (biru) bisa Anda ubah. Sel kuning = perlu Anda verifikasi. Kolom Pesaing punya dan Penilaian dihitung otomatis. Gunakan filter di baris judul.
A4: No | B4: Kelompok | C4: Fitur | D4: MELD | E4: Bukti MELD | F4: Monveo | G4: Bukti Monveo | H4: Status kita | I4: Catatan kita | J4: Pesaing punya | K4: Penilaian | L4: Prioritas (saran) | M4: Catatan peluang
A5: 1 | B5: Capture & input | C5: Input manual transaksi | D5: Ada | E5: Tombol + di semua halaman [SS] | F5: Ada | G5: Tombol Add Manual [SS] | H5: Ada | I5: Form Add Transaction [SS] | J5: =IF(OR(D5="Ada",D5="Ada (klaim)",D5="Pro"),1,0)+IF(OR(F5="Ada",F5="Ada (klaim)",F5="Pro"),1,0) -> 2 | K5: =IF(H5="Perlu cek","VERIFIKASI",IF(J5>0,IF(H5="Ada","Setara",IF(J5=2,"GAP BESAR","GAP")),IF(OR(D5="Perlu cek",F5="Perlu cek"),IF(H5="Ada","CEK PESAING","PELUANG (cek)"),IF(H5="Ada","KEUNGGULAN UNIK","PELUANG")))) -> Setara | L5: Rendah | M5: Sudah setara.
A6: 2 | B6: Capture & input | C6: Kalkulator di kolom nominal | D6: Ada (klaim) | E6: Tutorial 'Kalkulator Transaksi' [SS]; mekanisme belum terlihat | F6: Perlu cek | G6: Setelan 'Amount keyboard: Standard' menyiratkan opsi lain [SS] | H6: Tidak terlihat | I6: Hanya chip nominal [SS] | J6: =IF(OR(D6="Ada",D6="Ada (klaim)",D6="Pro"),1,0)+IF(OR(F6="Ada",F6="Ada (klaim)",F6="Pro"),1,0) -> 1 | K6: =IF(H6="Perlu cek","VERIFIKASI",IF(J6>0,IF(H6="Ada","Setara",IF(J6=2,"GAP BESAR","GAP")),IF(OR(D6="Perlu cek",F6="Perlu cek"),IF(H6="Ada","CEK PESAING","PELUANG (cek)"),IF(H6="Ada","KEUNGGULAN UNIK","PELUANG")))) -> GAP | L6: Sedang | M6: Ekspresi 25000+15000 dan 50000*2; murah dan terasa pintar.
A7: 3 | B7: Capture & input | C7: Chip nominal cepat | D7: Perlu cek | E7: Form tambah belum tertangkap screenshot | F7: Perlu cek | G7: Form tambah belum tertangkap screenshot | H7: Ada | I7: 50rb sampai 1jt [SS] | J7: =IF(OR(D7="Ada",D7="Ada (klaim)",D7="Pro"),1,0)+IF(OR(F7="Ada",F7="Ada (klaim)",F7="Pro"),1,0) -> 0 | K7: =IF(H7="Perlu cek","VERIFIKASI",IF(J7>0,IF(H7="Ada","Setara",IF(J7=2,"GAP BESAR","GAP")),IF(OR(D7="Perlu cek",F7="Perlu cek"),IF(H7="Ada","CEK PESAING","PELUANG (cek)"),IF(H7="Ada","KEUNGGULAN UNIK","PELUANG")))) -> CEK PESAING | L7: Rendah | M7: Jadikan dinamis per kategori dari riwayat.
A8: 4 | B8: Capture & input | C8: Ketik cepat bahasa natural | D8: Pro | E8: 'AI Otomatis: deteksi kategori, jumlah, tipe' terkunci Pro [SS] | F8: Ada | G8: Input natural; tip multi-transaksi [SS] | H8: Sebagian | I8: Diklaim agent (v20); kualitas parser belum terverifikasi [Log] | J8: =IF(OR(D8="Ada",D8="Ada (klaim)",D8="Pro"),1,0)+IF(OR(F8="Ada",F8="Ada (klaim)",F8="Pro"),1,0) -> 2 | K8: =IF(H8="Perlu cek","VERIFIKASI",IF(J8>0,IF(H8="Ada","Setara",IF(J8=2,"GAP BESAR","GAP")),IF(OR(D8="Perlu cek",F8="Perlu cek"),IF(H8="Ada","CEK PESAING","PELUANG (cek)"),IF(H8="Ada","KEUNGGULAN UNIK","PELUANG")))) -> GAP BESAR | L8: Tinggi | M8: Stabilkan dengan golden test sebelum menambah fitur lain.
A9: 5 | B9: Capture & input | C9: Input suara | D9: Ada (klaim) | E9: Play: AI Voice Command; Voice Note via Telegram terkunci Pro [Play,SS] | F9: Ada | G9: Mikrofon + pilihan bahasa ID [SS] | H9: Tidak terlihat | I9: - | J9: =IF(OR(D9="Ada",D9="Ada (klaim)",D9="Pro"),1,0)+IF(OR(F9="Ada",F9="Ada (klaim)",F9="Pro"),1,0) -> 2 | K9: =IF(H9="Perlu cek","VERIFIKASI",IF(J9>0,IF(H9="Ada","Setara",IF(J9=2,"GAP BESAR","GAP")),IF(OR(D9="Perlu cek",F9="Perlu cek"),IF(H9="Ada","CEK PESAING","PELUANG (cek)"),IF(H9="Ada","KEUNGGULAN UNIK","PELUANG")))) -> GAP BESAR | L9: Sedang | M9: Web Speech API untuk prototipe; masuk ke parser yang sama. Audio di Chrome dapat diproses server Google.
A10: 6 | B10: Capture & input | C10: Multi-transaksi dalam satu kalimat | D10: Perlu cek | E10: - | F10: Ada | G10: Tip 'coffee 20k and parking 5k' [SS] | H10: Tidak terlihat | I10: - | J10: =IF(OR(D10="Ada",D10="Ada (klaim)",D10="Pro"),1,0)+IF(OR(F10="Ada",F10="Ada (klaim)",F10="Pro"),1,0) -> 1 | K10: =IF(H10="Perlu cek","VERIFIKASI",IF(J10>0,IF(H10="Ada","Setara",IF(J10=2,"GAP BESAR","GAP")),IF(OR(D10="Perlu cek",F10="Perlu cek"),IF(H10="Ada","CEK PESAING","PELUANG (cek)"),IF(H10="Ada","KEUNGGULAN UNIK","PELUANG")))) -> GAP | L10: Sedang | M10: Pisah hanya jika tiap segmen punya nominal sendiri.
A11: 7 | B11: Capture & input | C11: Scan struk (OCR/AI) | D11: Ada (klaim) | E11: Play: AI Receipt Capture; versi Telegram terkunci Pro [Play,SS] | F11: Ada | G11: Dialog 'Receipt details not recognized' [SS] | H11: Tidak terlihat | I11: - | J11: =IF(OR(D11="Ada",D11="Ada (klaim)",D11="Pro"),1,0)+IF(OR(F11="Ada",F11="Ada (klaim)",F11="Pro"),1,0) -> 2 | K11: =IF(H11="Perlu cek","VERIFIKASI",IF(J11>0,IF(H11="Ada","Setara",IF(J11=2,"GAP BESAR","GAP")),IF(OR(D11="Perlu cek",F11="Perlu cek"),IF(H11="Ada","CEK PESAING","PELUANG (cek)"),IF(H11="Ada","KEUNGGULAN UNIK","PELUANG")))) -> GAP BESAR | L11: Rendah | M11: Tunda: akurasi struk Indonesia belum konsisten, bahkan di Monveo.
A12: 8 | B12: Capture & input | C12: Berbagi struk/screenshot dari aplikasi lain | D12: Perlu cek | E12: - | F12: Ada | G12: Share Extension iOS [Web] | H12: Tidak terlihat | I12: - | J12: =IF(OR(D12="Ada",D12="Ada (klaim)",D12="Pro"),1,0)+IF(OR(F12="Ada",F12="Ada (klaim)",F12="Pro"),1,0) -> 1 | K12: =IF(H12="Perlu cek","VERIFIKASI",IF(J12>0,IF(H12="Ada","Setara",IF(J12=2,"GAP BESAR","GAP")),IF(OR(D12="Perlu cek",F12="Perlu cek"),IF(H12="Ada","CEK PESAING","PELUANG (cek)"),IF(H12="Ada","KEUNGGULAN UNIK","PELUANG")))) -> GAP | L12: Rendah | M12: Web Share Target hanya Android; verifikasi dukungan.
A13: 9 | B13: Capture & input | C13: Pembaca notifikasi menjadi draf | D13: Ada (klaim) | E13: Bagian 'Pencatatan otomatis: biar Meld yang mengetik, kamu cukup memeriksa'; mekanisme terpotong [SS] | F13: Ada | G13: 'Notification Reader: Review drafts' (Android) [SS] | H13: Tidak terlihat | I13: - | J13: =IF(OR(D13="Ada",D13="Ada (klaim)",D13="Pro"),1,0)+IF(OR(F13="Ada",F13="Ada (klaim)",F13="Pro"),1,0) -> 2 | K13: =IF(H13="Perlu cek","VERIFIKASI",IF(J13>0,IF(H13="Ada","Setara",IF(J13=2,"GAP BESAR","GAP")),IF(OR(D13="Perlu cek",F13="Perlu cek"),IF(H13="Ada","CEK PESAING","PELUANG (cek)"),IF(H13="Ada","KEUNGGULAN UNIK","PELUANG")))) -> GAP BESAR | L13: Tinggi | M13: Versi web lewat tempel teks (baris berikutnya).
A14: 10 | B14: Capture & input | C14: Tempel teks notifikasi/SMS bank | D14: Perlu cek | E14: - | F14: Tidak terlihat | G14: Tidak ada di pengaturan [SS] | H14: Tidak terlihat | I14: Rencana | J14: =IF(OR(D14="Ada",D14="Ada (klaim)",D14="Pro"),1,0)+IF(OR(F14="Ada",F14="Ada (klaim)",F14="Pro"),1,0) -> 0 | K14: =IF(H14="Perlu cek","VERIFIKASI",IF(J14>0,IF(H14="Ada","Setara",IF(J14=2,"GAP BESAR","GAP")),IF(OR(D14="Perlu cek",F14="Perlu cek"),IF(H14="Ada","CEK PESAING","PELUANG (cek)"),IF(H14="Ada","KEUNGGULAN UNIK","PELUANG")))) -> PELUANG (cek) | L14: Tinggi | M14: Pembeda: tanpa izin sensitif, 100% di klien. Butuh contoh teks asli.
A15: 11 | B15: Capture & input | C15: Draf / tinjau sebelum final | D15: Perlu cek | E15: - | F15: Ada | G15: 'Review drafts' [SS] | H15: Tidak terlihat | I15: Rencana | J15: =IF(OR(D15="Ada",D15="Ada (klaim)",D15="Pro"),1,0)+IF(OR(F15="Ada",F15="Ada (klaim)",F15="Pro"),1,0) -> 1 | K15: =IF(H15="Perlu cek","VERIFIKASI",IF(J15>0,IF(H15="Ada","Setara",IF(J15=2,"GAP BESAR","GAP")),IF(OR(D15="Perlu cek",F15="Perlu cek"),IF(H15="Ada","CEK PESAING","PELUANG (cek)"),IF(H15="Ada","KEUNGGULAN UNIK","PELUANG")))) -> GAP | L15: Tinggi | M15: Fondasi semua capture otomatis; draf tidak mengubah saldo.
A16: 12 | B16: Capture & input | C16: Catat via bot Telegram | D16: Pro | E16: 'Catat via Telegram' terkunci Pro [SS] | F16: Tidak terlihat | G16: - | H16: Tidak terlihat | I16: - | J16: =IF(OR(D16="Ada",D16="Ada (klaim)",D16="Pro"),1,0)+IF(OR(F16="Ada",F16="Ada (klaim)",F16="Pro"),1,0) -> 1 | K16: =IF(H16="Perlu cek","VERIFIKASI",IF(J16>0,IF(H16="Ada","Setara",IF(J16=2,"GAP BESAR","GAP")),IF(OR(D16="Perlu cek",F16="Perlu cek"),IF(H16="Ada","CEK PESAING","PELUANG (cek)"),IF(H16="Ada","KEUNGGULAN UNIK","PELUANG")))) -> GAP | L16: Rendah | M16: Risiko privasi; tunda.
... A25: 21 | B25: Akun & kategori | C25: Logo bank & e-wallet Indonesia | D25: Ada (klaim) | E25: Play | F25: Ada (klaim) | G25: Daftar BCA, BRImo, GoPay, OVO dst. [Web] | H25: Tidak terlihat | I25: Ikon generik [SS] | J25: =IF(OR(D25="Ada",D25="Ada (klaim)",D25="Pro"),1,0)+IF(OR(F25="Ada",F25="Ada (klaim)",F25="Pro"),1,0) -> 2 | K25: =IF(H25="Perlu cek","VERIFIKASI",IF(J25>0,IF(H25="Ada","Setara",IF(J25=2,"GAP BESAR","GAP")),IF(OR(D25="Perlu cek",F25="Perlu cek"),IF(H25="Ada","CEK PESAING","PELUANG (cek)"),IF(H25="Ada","KEUNGGULAN UNIK","PELUANG")))) -> GAP BESAR | L25: Sedang | M25: Logo adalah merek dagang; mulai dari inisial berwarna.
A26: 22 | B26: Akun & kategori | C26: Kategori kustom | D26: Ada | E26: '+ Kategori' [SS] | F26: Ada | G26: 'Category & Budget' [SS] | H26: Perlu cek | I26: - | J26: =IF(OR(D26="Ada",D26="Ada (klaim)",D26="Pro"),1,0)+IF(OR(F26="Ada",F26="Ada (klaim)",F26="Pro"),1,0) -> 2 | K26: =IF(H26="Perlu cek","VERIFIKASI",IF(J26>0,IF(H26="Ada","Setara",IF(J26=2,"GAP BESAR","GAP")),IF(OR(D26="Perlu cek",F26="Perlu cek"),IF(H26="Ada","CEK PESAING","PELUANG (cek)"),IF(H26="Ada","KEUNGGULAN UNIK","PELUANG")))) -> VERIFIKASI | L26: Rendah
A27: 23 | B27: Akun & kategori | C27: Kelompok Kebutuhan/Keinginan | D27: Ada | E27: Tampilan 'stiker' per kelompok [SS] | F27: Tidak terlihat | G27: - | H27: Tidak terlihat | I27: - | J27: =IF(OR(D27="Ada",D27="Ada (klaim)",D27="Pro"),1,0)+IF(OR(F27="Ada",F27="Ada (klaim)",F27="Pro"),1,0) -> 1 | K27: =IF(H27="Perlu cek","VERIFIKASI",IF(J27>0,IF(H27="Ada","Setara",IF(J27=2,"GAP BESAR","GAP")),IF(OR(D27="Perlu cek",F27="Perlu cek"),IF(H27="Ada","CEK PESAING","PELUANG (cek)"),IF(H27="Ada","KEUNGGULAN UNIK","PELUANG")))) -> GAP | L27: Sedang | M27: Dasar untuk 50/30/20.
A28: 24 | B28: Akun & kategori | C28: Kategori 'Penyesuaian Saldo' | D28: Ada | E28: Terlihat di daftar kategori [SS] | F28: Perlu cek | G28: - | H28: Tidak terlihat | I28: - | J28: =IF(OR(D28="Ada",D28="Ada (klaim)",D28="Pro"),1,0)+IF(OR(F28="Ada",F28="Ada (klaim)",F28="Pro"),1,0) -> 1 | K28: =IF(H28="Perlu cek","VERIFIKASI",IF(J28>0,IF(H28="Ada","Setara",IF(J28=2,"GAP BESAR","GAP")),IF(OR(D28="Perlu cek",F28="Perlu cek"),IF(H28="Ada","CEK PESAING","PELUANG (cek)"),IF(H28="Ada","KEUNGGULAN UNIK","PELUANG")))) -> GAP | L28: Sedang | M28: Rekonsiliasi saldo tanpa merusak laporan.
A29: 25 | B29: Akun & kategori | C29: Label / Tag | D29: Ada | E29: Menu Label [SS] | F29: Ada | G29: Tag, default Off [SS] | H29: Perlu cek | I29: - | J29: =IF(OR(D29="Ada",D29="Ada (klaim)",D29="Pro"),1,0)+IF(OR(F29="Ada",F29="Ada (klaim)",F29="Pro"),1,0) -> 2 | K29: =IF(H29="Perlu cek","VERIFIKASI",IF(J29>0,IF(H29="Ada","Setara",IF(J29=2,"GAP BESAR","GAP")),IF(OR(D29="Perlu cek",F29="Perlu cek"),IF(H29="Ada","CEK PESAING","PELUANG (cek)"),IF(H29="Ada","KEUNGGULAN UNIK","PELUANG")))) -> VERIFIKASI | L29: Rendah | M29: Default nonaktif (progressive disclosure).
A30: 26 | B30: Akun & kategori | C30: Multi mata uang | D30: Ada (klaim) | E30: Pencarian pengaturan menyebut 'mata uang' [SS] | F30: Perlu cek | G30: Mendukung PayPal/Wise [Web] | H30: Perlu cek | I30: - | J30: =IF(OR(D30="Ada",D30="Ada (klaim)",D30="Pro"),1,0)+IF(OR(F30="Ada",F30="Ada (klaim)",F30="Pro"),1,0) -> 1 | K30: =IF(H30="Perlu cek","VERIFIKASI",IF(J30>0,IF(H30="Ada","Setara",IF(J30=2,"GAP BESAR","GAP")),IF(OR(D30="Perlu cek",F30="Perlu cek"),IF(H30="Ada","CEK PESAING","PELUANG (cek)"),IF(H30="Ada","KEUNGGULAN UNIK","PELUANG")))) -> VERIFIKASI | L30: Rendah
A31: 27 | B31: Akun & kategori | C31: Onboarding pilih kategori awal | D31: Perlu cek | E31: - | F31: Ada | G31: 'Pick your first categories' [SS] | H31: Tidak terlihat | I31: - | J31: =IF(OR(D31="Ada",D31="Ada (klaim)",D31="Pro"),1,0)+IF(OR(F31="Ada",F31="Ada (klaim)",F31="Pro"),1,0) -> 1 | K31: =IF(H31="Perlu cek","VERIFIKASI",IF(J31>0,IF(H31="Ada","Setara",IF(J31=2,"GAP BESAR","GAP")),IF(OR(D31="Perlu cek",F31="Perlu cek"),IF(H31="Ada","CEK PESAING","PELUANG (cek)"),IF(H31="Ada","KEUNGGULAN UNIK","PELUANG")))) -> GAP | L31: Tinggi | M31: Sekaligus memetakan system_key.
A32: 28 | B32: Akun & kategori | C32: Checklist kesiapan akun | D32: Ada | E32: 'Setup', 'Kesiapan akun 0 dari 1', 'Lengkapi Profil Keuangan' [SS] | F32: Tidak terlihat | G32: - | H32: Tidak terlihat | I32: - | J32: =IF(OR(D32="Ada",D32="Ada (klaim)",D32="Pro"),1,0)+IF(OR(F32="Ada",F32="Ada (klaim)",F32="Pro"),1,0) -> 1 | K32: =IF(H32="Perlu cek","VERIFIKASI",IF(J32>0,IF(H32="Ada","Setara",IF(J32=2,"GAP BESAR","GAP")),IF(OR(D32="Perlu cek",F32="Perlu cek"),IF(H32="Ada","CEK PESAING","PELUANG (cek)"),IF(H32="Ada","KEUNGGULAN UNIK","PELUANG")))) -> GAP | L32: Sedang
A33: 29 | B33: Tagihan & berulang | C33: Transaksi berulang | D33: Ada (klaim) | E33: Auto-deposit gaji & auto-debit [Play] | F33: Ada | G33: 'Recurring Transaction' [SS] | H33: Perlu cek | I33: - | J33: =IF(OR(D33="Ada",D33="Ada (klaim)",D33="Pro"),1,0)+IF(OR(F33="Ada",F33="Ada (klaim)",F33="Pro"),1,0) -> 2 | K33: =IF(H33="Perlu cek","VERIFIKASI",IF(J33>0,IF(H33="Ada","Setara",IF(J33=2,"GAP BESAR","GAP")),IF(OR(D33="Perlu cek",F33="Perlu cek"),IF(H33="Ada","CEK PESAING","PELUANG (cek)"),IF(H33="Ada","KEUNGGULAN UNIK","PELUANG")))) -> VERIFIKASI | L33: Tinggi | M33: Fondasi Uang Aman Harian dan feed ICS.
A34: 30 | B34: Tagihan & berulang | C34: Pelacak langganan | D34: Ada | E34: 'Add Subscription': 21 layanan, siklus bulanan/tahunan/kustom, hari tagih 1-31 [SS] | F34: Tidak terlihat | G34: - | H34: Perlu cek | I34: - | J34: =IF(OR(D34="Ada",D34="Ada (klaim)",D34="Pro"),1,0)+IF(OR(F34="Ada",F34="Ada (klaim)",F34="Pro"),1,0) -> 1 | K34: =IF(H34="Perlu cek","VERIFIKASI",IF(J34>0,IF(H34="Ada","Setara",IF(J34=2,"GAP BESAR","GAP")),IF(OR(D34="Perlu cek",F34="Perlu cek"),IF(H34="Ada","CEK PESAING","PELUANG (cek)"),IF(H34="Ada","KEUNGGULAN UNIK","PELUANG")))) -> VERIFIKASI | L34: Tinggi | M34: Daftar layanan MELD condong ke AS; tambahkan layanan Indonesia.
A35: 31 | B35: Tagihan & berulang | C35: Pengingat sebelum jatuh tempo | D35: Ada | E35: 1/2/3/5/7 hari + kustom, 0 = hari-H [SS] | F35: Ada | G35: 'Reminder' dan 'Reminders' [SS] | H35: Tidak terlihat | I35: - | J35: =IF(OR(D35="Ada",D35="Ada (klaim)",D35="Pro"),1,0)+IF(OR(F35="Ada",F35="Ada (klaim)",F35="Pro"),1,0) -> 2 | K35: =IF(H35="Perlu cek","VERIFIKASI",IF(J35>0,IF(H35="Ada","Setara",IF(J35=2,"GAP BESAR","GAP")),IF(OR(D35="Perlu cek",F35="Perlu cek"),IF(H35="Ada","CEK PESAING","PELUANG (cek)"),IF(H35="Ada","KEUNGGULAN UNIK","PELUANG")))) -> GAP BESAR | L35: Tinggi | M35: Opt-in; masuk ke feed ICS.
A36: 32 | B36: Tagihan & berulang | C36: Auto-debit saat tanggal tagih | D36: Pro | E36: 'Auto-debit (Pro)' [SS] | F36: Perlu cek | G36: - | H36: Tidak terlihat | I36: - | J36: =IF(OR(D36="Ada",D36="Ada (klaim)",D36="Pro"),1,0)+IF(OR(F36="Ada",F36="Ada (klaim)",F36="Pro"),1,0) -> 1 | K36: =IF(H36="Perlu cek","VERIFIKASI",IF(J36>0,IF(H36="Ada","Setara",IF(J36=2,"GAP BESAR","GAP")),IF(OR(D36="Perlu cek",F36="Perlu cek"),IF(H36="Ada","CEK PESAING","PELUANG (cek)"),IF(H36="Ada","KEUNGGULAN UNIK","PELUANG")))) -> GAP | L36: Sedang | M36: Hasilkan draf, bukan transaksi final.
A37: 33 | B37: Tagihan & berulang | C37: Auto-input gaji | D37: Ada (klaim) | E37: Play | F37: Perlu cek | G37: - | H37: Tidak terlihat | I37: - | J37: =IF(OR(D37="Ada",D37="Ada (klaim)",D37="Pro"),1,0)+IF(OR(F37="Ada",F37="Ada (klaim)",F37="Pro"),1,0) -> 1 | K37: =IF(H37="Perlu cek","VERIFIKASI",IF(J37>0,IF(H37="Ada","Setara",IF(J37=2,"GAP BESAR","GAP")),IF(OR(D37="Perlu cek",F37="Perlu cek"),IF(H37="Ada","CEK PESAING","PELUANG (cek)"),IF(H37="Ada","KEUNGGULAN UNIK","PELUANG")))) -> GAP | L37: Sedang
A38: 34 | B38: Tagihan & berulang | C38: Pengingat harian untuk mencatat | D38: Ada | E38: 'Izinkan pengingat harian' [SS] | F38: Ada | G38: 'Daily reminder' [SS] | H38: Tidak terlihat | I38: - | J38: =IF(OR(D38="Ada",D38="Ada (klaim)",D38="Pro"),1,0)+IF(OR(F38="Ada",F38="Ada (klaim)",F38="Pro"),1,0) -> 2 | K38: =IF(H38="Perlu cek","VERIFIKASI",IF(J38>0,IF(H38="Ada","Setara",IF(J38=2,"GAP BESAR","GAP")),IF(OR(D38="Perlu cek",F38="Perlu cek"),IF(H38="Ada","CEK PESAING","PELUANG (cek)"),IF(H38="Ada","KEUNGGULAN UNIK","PELUANG")))) -> GAP BESAR | L38: Sedang | M38: Opt-in dengan pilihan jam.
A39: 35 | B39: Tagihan & berulang | C39: Insight mingguan/bulanan | D39: Perlu cek | E39: - | F39: Ada | G39: Weekly & Monthly insight [SS] | H39: Tidak terlihat | I39: - | J39: =IF(OR(D39="Ada",D39="Ada (klaim)",D39="Pro"),1,0)+IF(OR(F39="Ada",F39="Ada (klaim)",F39="Pro"),1,0) -> 1 | K39: =IF(H39="Perlu cek","VERIFIKASI",IF(J39>0,IF(H39="Ada","Setara",IF(J39=2,"GAP BESAR","GAP")),IF(OR(D39="Perlu cek",F39="Perlu cek"),IF(H39="Ada","CEK PESAING","PELUANG (cek)"),IF(H39="Ada","KEUNGGULAN UNIK","PELUANG")))) -> GAP | L39: Sedang
A40: 36 | B40: Tagihan & berulang | C40: Utang-piutang | D40: Ada (klaim) | E40: Play: Accounts Payable & Receivable | F40: Tidak terlihat | G40: - | H40: Tidak terlihat | I40: - | J40: =IF(OR(D40="Ada",D40="Ada (klaim)",D40="Pro"),1,0)+IF(OR(F40="Ada",F40="Ada (klaim)",F40="Pro"),1,0) -> 1 | K40: =IF(H40="Perlu cek","VERIFIKASI",IF(J40>0,IF(H40="Ada","Setara",IF(J40=2,"GAP BESAR","GAP")),IF(OR(D40="Perlu cek",F40="Perlu cek"),IF(H40="Ada","CEK PESAING","PELUANG (cek)"),IF(H40="Ada","KEUNGGULAN UNIK","PELUANG")))) -> GAP | L40: Tinggi | M40: Pengingat sopan via wa.me.
A41: 37 | B41: Perencanaan | C41: Budget per kategori | D41: Ada | E41: 'Tambah Anggaran' [SS] | F41: Ada | G41: 'Category & Budget' [SS] | H41: Perlu cek | I41: - | J41: =IF(OR(D41="Ada",D41="Ada (klaim)",D41="Pro"),1,0)+IF(OR(F41="Ada",F41="Ada (klaim)",F41="Pro"),1,0) -> 2 | K41: =IF(H41="Perlu cek","VERIFIKASI",IF(J41>0,IF(H41="Ada","Setara",IF(J41=2,"GAP BESAR","GAP")),IF(OR(D41="Perlu cek",F41="Perlu cek"),IF(H41="Ada","CEK PESAING","PELUANG (cek)"),IF(H41="Ada","KEUNGGULAN UNIK","PELUANG")))) -> VERIFIKASI | L41: Tinggi
A42: 38 | B42: Perencanaan | C42: Smart Budget 50/30/20 + resep | D42: Ada | E42: Wizard 5 langkah; 4 resep (Si Seimbang dst.); slider [SS] | F42: Tidak terlihat | G42: - | H42: Tidak terlihat | I42: - | J42: =IF(OR(D42="Ada",D42="Ada (klaim)",D42="Pro"),1,0)+IF(OR(F42="Ada",F42="Ada (klaim)",F42="Pro"),1,0) -> 1 | K42: =IF(H42="Perlu cek","VERIFIKASI",IF(J42>0,IF(H42="Ada","Setara",IF(J42=2,"GAP BESAR","GAP")),IF(OR(D42="Perlu cek",F42="Perlu cek"),IF(H42="Ada","CEK PESAING","PELUANG (cek)"),IF(H42="Ada","KEUNGGULAN UNIK","PELUANG")))) -> GAP | L42: Sedang | M42: Resep bernama karakter membuat budgeting terasa seperti cerita.
A43: 39 | B43: Perencanaan | C43: Batas aman per hari | D43: Ada | E43: 'Rp500.0K/hari', 'posisi aman hari ini' [SS] | F43: Tidak terlihat | G43: - | H43: Tidak terlihat | I43: Rencana | J43: =IF(OR(D43="Ada",D43="Ada (klaim)",D43="Pro"),1,0)+IF(OR(F43="Ada",F43="Ada (klaim)",F43="Pro"),1,0) -> 1 | K43: =IF(H43="Perlu cek","VERIFIKASI",IF(J43>0,IF(H43="Ada","Setara",IF(J43=2,"GAP BESAR","GAP")),IF(OR(D43="Perlu cek",F43="Perlu cek"),IF(H43="Ada","CEK PESAING","PELUANG (cek)"),IF(H43="Ada","KEUNGGULAN UNIK","PELUANG")))) -> GAP | L43: Tinggi | M43: Ide ini sudah ada di MELD. Pembeda kita: kurangi tagihan yang akan datang.
A44: 40 | B44: Perencanaan | C44: Awal periode budget (tanggal gajian) | D44: Perlu cek | E44: Periode tampil 1-31 Okt [SS] | F44: Ada | G44: 'Budget period start' [SS] | H44: Tidak terlihat | I44: Rencana | J44: =IF(OR(D44="Ada",D44="Ada (klaim)",D44="Pro"),1,0)+IF(OR(F44="Ada",F44="Ada (klaim)",F44="Pro"),1,0) -> 1 | K44: =IF(H44="Perlu cek","VERIFIKASI",IF(J44>0,IF(H44="Ada","Setara",IF(J44=2,"GAP BESAR","GAP")),IF(OR(D44="Perlu cek",F44="Perlu cek"),IF(H44="Ada","CEK PESAING","PELUANG (cek)"),IF(H44="Ada","KEUNGGULAN UNIK","PELUANG")))) -> GAP | L44: Tinggi | M44: Uji tanggal 29-31.
A45: 41 | B45: Perencanaan | C45: Target tabungan + proyeksi tanggal | D45: Ada | E45: Timeline Jan 2028, Rp1,2jt/bln [SS] | F45: Ada | G45: 'Goals' [SS] | H45: Perlu cek | I45: - | J45: =IF(OR(D45="Ada",D45="Ada (klaim)",D45="Pro"),1,0)+IF(OR(F45="Ada",F45="Ada (klaim)",F45="Pro"),1,0) -> 2 | K45: =IF(H45="Perlu cek","VERIFIKASI",IF(J45>0,IF(H45="Ada","Setara",IF(J45=2,"GAP BESAR","GAP")),IF(OR(D45="Perlu cek",F45="Perlu cek"),IF(H45="Ada","CEK PESAING","PELUANG (cek)"),IF(H45="Ada","KEUNGGULAN UNIK","PELUANG")))) -> VERIFIKASI | L45: Sedang
A46: 42 | B46: Perencanaan | C46: Target dana darurat otomatis | D46: Ada | E46: 6x Kebutuhan = Rp18.000.000 [SS] | F46: Tidak terlihat | G46: - | H46: Tidak terlihat | I46: - | J46: =IF(OR(D46="Ada",D46="Ada (klaim)",D46="Pro"),1,0)+IF(OR(F46="Ada",F46="Ada (klaim)",F46="Pro"),1,0) -> 1 | K46: =IF(H46="Perlu cek","VERIFIKASI",IF(J46>0,IF(H46="Ada","Setara",IF(J46=2,"GAP BESAR","GAP")),IF(OR(D46="Perlu cek",F46="Perlu cek"),IF(H46="Ada","CEK PESAING","PELUANG (cek)"),IF(H46="Ada","KEUNGGULAN UNIK","PELUANG")))) -> GAP | L46: Sedang
A47: 43 | B47: Perencanaan | C47: Net worth (aset & liabilitas) | D47: Ada | E47: Tutorial 'Networth' [SS] | F47: Ada | G47: Aset & liabilitas [Web] | H47: Tidak terlihat | I47: - | J47: =IF(OR(D47="Ada",D47="Ada (klaim)",D47="Pro"),1,0)+IF(OR(F47="Ada",F47="Ada (klaim)",F47="Pro"),1,0) -> 2 | K47: =IF(H47="Perlu cek","VERIFIKASI",IF(J47>0,IF(H47="Ada","Setara",IF(J47=2,"GAP BESAR","GAP")),IF(OR(D47="Perlu cek",F47="Perlu cek"),IF(H47="Ada","CEK PESAING","PELUANG (cek)"),IF(H47="Ada","KEUNGGULAN UNIK","PELUANG")))) -> GAP BESAR | L47: Sedang
A48: 44 | B48: Perencanaan | C48: Kesehatan finansial (skor + saran) | D48: Ada | E48: Menu terlihat; isi belum dibuka [SS] | F48: Tidak terlihat | G48: - | H48: Perlu cek | I48: Teks terminal di screenshot menyiratkan rute health-coach; belum jelas | J48: =IF(OR(D48="Ada",D48="Ada (klaim)",D48="Pro"),1,0)+IF(OR(F48="Ada",F48="Ada (klaim)",F48="Pro"),1,0) -> 1 | K48: =IF(H48="Perlu cek","VERIFIKASI",IF(J48>0,IF(H48="Ada","Setara",IF(J48=2,"GAP BESAR","GAP")),IF(OR(D48="Perlu cek",F48="Perlu cek"),IF(H48="Ada","CEK PESAING","PELUANG (cek)"),IF(H48="Ada","KEUNGGULAN UNIK","PELUANG")))) -> VERIFIKASI | L48: Sedang | M48: Berbasis aturan; tampilkan rumus.
A49: 45 | B49: Perencanaan | C49: Asisten AI keuangan | D49: Ada (klaim) | E49: Play: AI Assistant | F49: Pro | G49: 'Ask Monveo' web, Pro [Web] | H49: Sebagian | I49: Endpoint AI Advice error di log, belum dilaporkan/diperbaiki [Log] | J49: =IF(OR(D49="Ada",D49="Ada (klaim)",D49="Pro"),1,0)+IF(OR(F49="Ada",F49="Ada (klaim)",F49="Pro"),1,0) -> 2 | K49: =IF(H49="Perlu cek","VERIFIKASI",IF(J49>0,IF(H49="Ada","Setara",IF(J49=2,"GAP BESAR","GAP")),IF(OR(D49="Perlu cek",F49="Perlu cek"),IF(H49="Ada","CEK PESAING","PELUANG (cek)"),IF(H49="Ada","KEUNGGULAN UNIK","PELUANG")))) -> GAP BESAR | L49: Sedang
...

Sheet Temuan MELD
A1: Temuan dari screenshot MELD (akun gratis, data kosong)
A3: Jenis | B3: Temuan | C3: Bukti | D3: Pelajaran untuk aplikasi kita
A4: Kelebihan | B4: Smart Budget berupa wizard 5 langkah: gaji, sortir, bagi, target, struk. Ada 'resep' bernama karakter (Si Seimbang, Si Pejuang Cuan, Si Anak Kota, Si Pelunas). | C4: /budgets, langkah 1-4 | D4: Budgeting terasa seperti cerita, bukan formulir. Tiru strukturnya, buat nama dan resep sendiri.
A5: Kelebihan | B5: Kategori disortir otomatis ke Kebutuhan/Keinginan dengan label 'tebakan' agar pengguna memeriksa sekaligus. | C5: Langkah 'Sortir': '7 ditebak otomatis, cek sekalian' | D5: Tampilkan tebakan sebagai tebakan. Sejalan dengan prinsip 'saran, bukan isi paksa'.
A6: Kelebihan | B6: Batas aman harian per kelompok (Rp500.0K/hari) dengan penanda 'posisi aman hari ini' dan toples visual. | C6: /budgets | D6: Ide 'Uang Aman Harian' sudah ada. Pembeda kita: kurangi tagihan dan langganan yang akan datang.
A7: Kelebihan | B7: Household memberi catatan jujur: mencentang barang tidak membuat transaksi; nominal dicatat saat pembelian benar-benar terjadi. | C7: Tab Kebutuhan | D7: Pisahkan rencana belanja dari transaksi nyata, lalu jembatani dengan draf.
A8: Kelebihan | B8: Form langganan lengkap: logo layanan, siklus, hari tagih 1-31, pengingat 1/2/3/5/7 hari + kustom, tanggal tagih berikutnya. | C8: /subscriptions | D8: Fitur kecil yang sangat konkret. Mudah ditiru dalam beberapa hari.
A9: Kelebihan | B9: Gamifikasi menyeluruh: Paspor (lencana), Kebun Meld, maskot kucing piksel, seri tutorial 'Boss Keuangan'. | C9: /settings, sidebar, tutorial | D9: Retensi lewat rasa progres. Cocok dengan tema pastel kita, tetapi jaga agar tidak membuat bersalah.
A10: Kelebihan | B10: Pencarian di Pengaturan dengan pintasan '/', serta tombol Install PWA di sidebar. | C10: /settings | D10: Murah dan terasa matang.
A11: Kelebihan | B11: Program referral dua tingkat plus program kreator (badge verified, landing khusus, revenue share). | C11: /meldfiliate | D11: Saluran akuisisi yang terbukti di Threads. Wajib ada pengungkapan kerja sama berbayar.
A12: Kekurangan | B12: Campuran Inggris dan Indonesia: form langganan, grafik (Weekly Expenses, Income vs Expenses), kutipan Franklin, contoh '$10 a week'. | C12: /subscriptions, /charts, /plan | D12: Peluang: UI Indonesia penuh dan konsisten.
A13: Kekurangan | B13: Daftar layanan langganan yang terlihat condong ke AS (Hulu, Peacock, Paramount+, Crunchyroll, Twitch); layanan Indonesia tidak tampak. | C13: /subscriptions | D13: Isi dengan layanan yang benar-benar dipakai orang Indonesia.
A14: Kekurangan | B14: Statistik pemasaran tanpa sumber di halaman Rencana (80%, 3-6x, 65%). | C14: /plan | D14: Jangan menampilkan angka klaim tanpa sumber, terutama di aplikasi keuangan.
... A20: Catatan | B20: Screenshot memuat email akun, kode undangan household, dan kode referral. Jangan dibagikan tanpa disamarkan. | C20: Screenshot 1-19 | D20: Kode undangan dapat dipakai orang lain untuk bergabung.

Sheet Cara Baca
A1: Cara membaca dan batasan
A3: Status | B3: Ada = terlihat langsung di screenshot atau halaman resmi. Ada (klaim) = hanya disebut di listing Play Store atau postingan Threads. Pro = terlihat tetapi terkunci berbayar. Sebagian = ada tetapi belum utuh atau belum terverifikasi. Tidak terlihat = tidak muncul di layar yang saya lihat (bukan bukti tidak ada). Perlu cek = layar terkait belum saya lihat.
A4: Tag bukti | B4: [SS] screenshot Anda. [Web] halaman resmi Monveo. [Play] listing Play Store MELD. [Thr] cuplikan Threads. [Log] log agent Hermes, klaim yang belum diverifikasi.
A5: Pesaing punya | B5: Jumlah pesaing (0-2) dengan status Ada, Ada (klaim), atau Pro. Sebagian tidak dihitung.
A6: Penilaian | B6: GAP BESAR: dua pesaing punya, kita belum/sebagian. GAP: satu pesaing punya. KEUNGGULAN UNIK: hanya kita yang Ada dan kedua pesaing dipastikan belum punya. CEK PESAING: kita Ada tetapi pesaing masih Perlu cek. PELUANG: pesaing dipastikan belum punya. PELUANG (cek): belum terlihat di pesaing, tetapi salah satunya masih Perlu cek. VERIFIKASI: status kita belum diisi.
A7: Batas 1 | B7: Akun MELD yang dilihat adalah akun gratis dengan data kosong. Fitur berbayar hanya terlihat sebagai label terkunci, dan isi analitik, AI, serta kesehatan finansial belum dinilai.
A8: Batas 2 | B8: Untuk Monveo saya memakai halaman resmi dan screenshot Android yang Anda kirim sebelumnya. Layar tambah transaksi dan analitik Monveo belum terlihat penuh.
A9: Batas 3 | B9: Untuk aplikasi Anda saya hanya mengetahui layar tambah transaksi, log agent, dan review sebelumnya. Banyak status 'Perlu cek' di kolom kita karena saya belum melihat layarnya. Isi sendiri dan sheet Ringkasan akan menghitung ulang.
A10: Batas 4 | B10: Daftar fitur dan harga pesaing dapat berubah. Ini potret per 26 Oktober 2026.
